{
 "cells": [
  {
   "cell_type": "code",
   "execution_count": null,
   "id": "bbfab42c-3c30-4928-88c2-f8e71824474f",
   "metadata": {
    "scrolled": true
   },
   "outputs": [
    {
     "name": "stdout",
     "output_type": "stream",
     "text": [
      " * Serving Flask app '__main__' (lazy loading)\n",
      " * Environment: production\n",
      "\u001b[31m   WARNING: This is a development server. Do not use it in a production deployment.\u001b[0m\n",
      "\u001b[2m   Use a production WSGI server instead.\u001b[0m\n",
      " * Debug mode: on\n"
     ]
    },
    {
     "name": "stderr",
     "output_type": "stream",
     "text": [
      "\u001b[31m\u001b[1mWARNING: This is a development server. Do not use it in a production deployment. Use a production WSGI server instead.\u001b[0m\n",
      " * Running on http://127.0.0.1:8049\n",
      "\u001b[33mPress CTRL+C to quit\u001b[0m\n",
      "127.0.0.1 - - [04/Oct/2023 15:49:36] \"GET / HTTP/1.1\" 200 -\n",
      "INFO:werkzeug:127.0.0.1 - - [04/Oct/2023 15:49:36] \"GET / HTTP/1.1\" 200 -\n",
      "127.0.0.1 - - [04/Oct/2023 15:49:36] \"\u001b[33mGET /favicon.ico HTTP/1.1\u001b[0m\" 404 -\n",
      "INFO:werkzeug:127.0.0.1 - - [04/Oct/2023 15:49:36] \"\u001b[33mGET /favicon.ico HTTP/1.1\u001b[0m\" 404 -\n",
      "127.0.0.1 - - [04/Oct/2023 15:55:34] \"\u001b[33mGET /videos/v_ArmFlapping_01.xml HTTP/1.1\u001b[0m\" 404 -\n",
      "INFO:werkzeug:127.0.0.1 - - [04/Oct/2023 15:55:34] \"\u001b[33mGET /videos/v_ArmFlapping_01.xml HTTP/1.1\u001b[0m\" 404 -\n",
      "127.0.0.1 - - [04/Oct/2023 15:55:40] \"\u001b[33mGET /videos/v_ArmFlapping_02.xml HTTP/1.1\u001b[0m\" 404 -\n",
      "INFO:werkzeug:127.0.0.1 - - [04/Oct/2023 15:55:40] \"\u001b[33mGET /videos/v_ArmFlapping_02.xml HTTP/1.1\u001b[0m\" 404 -\n",
      "127.0.0.1 - - [04/Oct/2023 15:58:09] \"\u001b[33mGET /videos/pexels-mikhail-nilov-8655759%20(1080p).mp4 HTTP/1.1\u001b[0m\" 404 -\n",
      "INFO:werkzeug:127.0.0.1 - - [04/Oct/2023 15:58:09] \"\u001b[33mGET /videos/pexels-mikhail-nilov-8655759%20(1080p).mp4 HTTP/1.1\u001b[0m\" 404 -\n",
      "OpenCV: Couldn't read video stream from file \"static/videos/pexels-mikhail-nilov-8655759 (1080p).mp4\"\n",
      "127.0.0.1 - - [04/Oct/2023 15:58:17] \"\u001b[35m\u001b[1mPOST /predict HTTP/1.1\u001b[0m\" 500 -\n",
      "INFO:werkzeug:127.0.0.1 - - [04/Oct/2023 15:58:17] \"\u001b[35m\u001b[1mPOST /predict HTTP/1.1\u001b[0m\" 500 -\n",
      "Traceback (most recent call last):\n",
      "  File \"/usr/local/lib/python3.11/site-packages/flask/app.py\", line 2091, in __call__\n",
      "    return self.wsgi_app(environ, start_response)\n",
      "           ^^^^^^^^^^^^^^^^^^^^^^^^^^^^^^^^^^^^^^\n",
      "  File \"/usr/local/lib/python3.11/site-packages/flask/app.py\", line 2076, in wsgi_app\n",
      "    response = self.handle_exception(e)\n",
      "               ^^^^^^^^^^^^^^^^^^^^^^^^\n",
      "  File \"/usr/local/lib/python3.11/site-packages/flask/app.py\", line 2073, in wsgi_app\n",
      "    response = self.full_dispatch_request()\n",
      "               ^^^^^^^^^^^^^^^^^^^^^^^^^^^^\n",
      "  File \"/usr/local/lib/python3.11/site-packages/flask/app.py\", line 1519, in full_dispatch_request\n",
      "    rv = self.handle_user_exception(e)\n",
      "         ^^^^^^^^^^^^^^^^^^^^^^^^^^^^^\n",
      "  File \"/usr/local/lib/python3.11/site-packages/flask/app.py\", line 1517, in full_dispatch_request\n",
      "    rv = self.dispatch_request()\n",
      "         ^^^^^^^^^^^^^^^^^^^^^^^\n",
      "  File \"/usr/local/lib/python3.11/site-packages/flask/app.py\", line 1503, in dispatch_request\n",
      "    return self.ensure_sync(self.view_functions[rule.endpoint])(**req.view_args)\n",
      "           ^^^^^^^^^^^^^^^^^^^^^^^^^^^^^^^^^^^^^^^^^^^^^^^^^^^^^^^^^^^^^^^^^^^^^\n",
      "  File \"/var/folders/2x/1d0r_dyn1snchg_l5_28mb100000gn/T/ipykernel_734/1631882613.py\", line 53, in predict\n",
      "    pred_time, (prediction_class, confidence) = predict_model(model, f\"static/videos/{file_name}\")\n",
      "                                                ^^^^^^^^^^^^^^^^^^^^^^^^^^^^^^^^^^^^^^^^^^^^^^^^^^\n",
      "  File \"/var/folders/2x/1d0r_dyn1snchg_l5_28mb100000gn/T/ipykernel_734/1631882613.py\", line 29, in predict_model\n",
      "    prediction = model.predict(np.array([data_matrix]))\n",
      "                 ^^^^^^^^^^^^^^^^^^^^^^^^^^^^^^^^^^^^^^\n",
      "  File \"/usr/local/lib/python3.11/site-packages/keras/src/utils/traceback_utils.py\", line 70, in error_handler\n",
      "    raise e.with_traceback(filtered_tb) from None\n",
      "  File \"/var/folders/2x/1d0r_dyn1snchg_l5_28mb100000gn/T/__autograph_generated_fileztntsymd.py\", line 18, in tf__predict_function\n",
      "    raise\n",
      "ValueError: in user code:\n",
      "\n",
      "    File \"/usr/local/lib/python3.11/site-packages/keras/src/engine/training.py\", line 2416, in predict_function  *\n",
      "        return step_function(self, iterator)\n",
      "    File \"/usr/local/lib/python3.11/site-packages/keras/src/engine/training.py\", line 2401, in step_function  **\n",
      "        outputs = model.distribute_strategy.run(run_step, args=(data,))\n",
      "    File \"/usr/local/lib/python3.11/site-packages/keras/src/engine/training.py\", line 2389, in run_step  **\n",
      "        outputs = model.predict_step(data)\n",
      "    File \"/usr/local/lib/python3.11/site-packages/keras/src/engine/training.py\", line 2357, in predict_step\n",
      "        return self(x, training=False)\n",
      "    File \"/usr/local/lib/python3.11/site-packages/keras/src/utils/traceback_utils.py\", line 70, in error_handler\n",
      "        raise e.with_traceback(filtered_tb) from None\n",
      "    File \"/usr/local/lib/python3.11/site-packages/keras/src/engine/input_spec.py\", line 235, in assert_input_compatibility\n",
      "        raise ValueError(\n",
      "\n",
      "    ValueError: Exception encountered when calling layer 'model' (type Functional).\n",
      "    \n",
      "    Input 0 of layer \"time_distributed\" is incompatible with the layer: expected ndim=5, found ndim=2. Full shape received: (None, 0)\n",
      "    \n",
      "    Call arguments received by layer 'model' (type Functional):\n",
      "      • inputs=tf.Tensor(shape=(None, 0), dtype=float32)\n",
      "      • training=False\n",
      "      • mask=None\n",
      "\n",
      "OpenCV: Couldn't read video stream from file \"static/videos/pexels-mikhail-nilov-8655759 (1080p).mp4\"\n",
      "127.0.0.1 - - [04/Oct/2023 15:58:19] \"\u001b[35m\u001b[1mPOST /predict HTTP/1.1\u001b[0m\" 500 -\n",
      "INFO:werkzeug:127.0.0.1 - - [04/Oct/2023 15:58:19] \"\u001b[35m\u001b[1mPOST /predict HTTP/1.1\u001b[0m\" 500 -\n",
      "Traceback (most recent call last):\n",
      "  File \"/usr/local/lib/python3.11/site-packages/flask/app.py\", line 2091, in __call__\n",
      "    return self.wsgi_app(environ, start_response)\n",
      "           ^^^^^^^^^^^^^^^^^^^^^^^^^^^^^^^^^^^^^^\n",
      "  File \"/usr/local/lib/python3.11/site-packages/flask/app.py\", line 2076, in wsgi_app\n",
      "    response = self.handle_exception(e)\n",
      "               ^^^^^^^^^^^^^^^^^^^^^^^^\n",
      "  File \"/usr/local/lib/python3.11/site-packages/flask/app.py\", line 2073, in wsgi_app\n",
      "    response = self.full_dispatch_request()\n",
      "               ^^^^^^^^^^^^^^^^^^^^^^^^^^^^\n",
      "  File \"/usr/local/lib/python3.11/site-packages/flask/app.py\", line 1519, in full_dispatch_request\n",
      "    rv = self.handle_user_exception(e)\n",
      "         ^^^^^^^^^^^^^^^^^^^^^^^^^^^^^\n",
      "  File \"/usr/local/lib/python3.11/site-packages/flask/app.py\", line 1517, in full_dispatch_request\n",
      "    rv = self.dispatch_request()\n",
      "         ^^^^^^^^^^^^^^^^^^^^^^^\n",
      "  File \"/usr/local/lib/python3.11/site-packages/flask/app.py\", line 1503, in dispatch_request\n",
      "    return self.ensure_sync(self.view_functions[rule.endpoint])(**req.view_args)\n",
      "           ^^^^^^^^^^^^^^^^^^^^^^^^^^^^^^^^^^^^^^^^^^^^^^^^^^^^^^^^^^^^^^^^^^^^^\n",
      "  File \"/var/folders/2x/1d0r_dyn1snchg_l5_28mb100000gn/T/ipykernel_734/1631882613.py\", line 53, in predict\n",
      "    pred_time, (prediction_class, confidence) = predict_model(model, f\"static/videos/{file_name}\")\n",
      "                                                ^^^^^^^^^^^^^^^^^^^^^^^^^^^^^^^^^^^^^^^^^^^^^^^^^^\n",
      "  File \"/var/folders/2x/1d0r_dyn1snchg_l5_28mb100000gn/T/ipykernel_734/1631882613.py\", line 29, in predict_model\n",
      "    prediction = model.predict(np.array([data_matrix]))\n",
      "                 ^^^^^^^^^^^^^^^^^^^^^^^^^^^^^^^^^^^^^^\n",
      "  File \"/usr/local/lib/python3.11/site-packages/keras/src/utils/traceback_utils.py\", line 70, in error_handler\n",
      "    raise e.with_traceback(filtered_tb) from None\n",
      "  File \"/var/folders/2x/1d0r_dyn1snchg_l5_28mb100000gn/T/__autograph_generated_fileztntsymd.py\", line 18, in tf__predict_function\n",
      "    raise\n",
      "ValueError: in user code:\n",
      "\n",
      "    File \"/usr/local/lib/python3.11/site-packages/keras/src/engine/training.py\", line 2416, in predict_function  *\n",
      "        return step_function(self, iterator)\n",
      "    File \"/usr/local/lib/python3.11/site-packages/keras/src/engine/training.py\", line 2401, in step_function  **\n",
      "        outputs = model.distribute_strategy.run(run_step, args=(data,))\n",
      "    File \"/usr/local/lib/python3.11/site-packages/keras/src/engine/training.py\", line 2389, in run_step  **\n",
      "        outputs = model.predict_step(data)\n",
      "    File \"/usr/local/lib/python3.11/site-packages/keras/src/engine/training.py\", line 2357, in predict_step\n",
      "        return self(x, training=False)\n",
      "    File \"/usr/local/lib/python3.11/site-packages/keras/src/utils/traceback_utils.py\", line 70, in error_handler\n",
      "        raise e.with_traceback(filtered_tb) from None\n",
      "    File \"/usr/local/lib/python3.11/site-packages/keras/src/engine/input_spec.py\", line 235, in assert_input_compatibility\n",
      "        raise ValueError(\n",
      "\n",
      "    ValueError: Exception encountered when calling layer 'model' (type Functional).\n",
      "    \n",
      "    Input 0 of layer \"time_distributed\" is incompatible with the layer: expected ndim=5, found ndim=2. Full shape received: (None, 0)\n",
      "    \n",
      "    Call arguments received by layer 'model' (type Functional):\n",
      "      • inputs=tf.Tensor(shape=(None, 0), dtype=float32)\n",
      "      • training=False\n",
      "      • mask=None\n",
      "\n",
      "OpenCV: Couldn't read video stream from file \"static/videos/pexels-mikhail-nilov-8655759 (1080p).mp4\"\n",
      "127.0.0.1 - - [04/Oct/2023 15:58:19] \"\u001b[35m\u001b[1mPOST /predict HTTP/1.1\u001b[0m\" 500 -\n",
      "INFO:werkzeug:127.0.0.1 - - [04/Oct/2023 15:58:19] \"\u001b[35m\u001b[1mPOST /predict HTTP/1.1\u001b[0m\" 500 -\n",
      "Traceback (most recent call last):\n",
      "  File \"/usr/local/lib/python3.11/site-packages/flask/app.py\", line 2091, in __call__\n",
      "    return self.wsgi_app(environ, start_response)\n",
      "           ^^^^^^^^^^^^^^^^^^^^^^^^^^^^^^^^^^^^^^\n",
      "  File \"/usr/local/lib/python3.11/site-packages/flask/app.py\", line 2076, in wsgi_app\n",
      "    response = self.handle_exception(e)\n",
      "               ^^^^^^^^^^^^^^^^^^^^^^^^\n",
      "  File \"/usr/local/lib/python3.11/site-packages/flask/app.py\", line 2073, in wsgi_app\n",
      "    response = self.full_dispatch_request()\n",
      "               ^^^^^^^^^^^^^^^^^^^^^^^^^^^^\n",
      "  File \"/usr/local/lib/python3.11/site-packages/flask/app.py\", line 1519, in full_dispatch_request\n",
      "    rv = self.handle_user_exception(e)\n",
      "         ^^^^^^^^^^^^^^^^^^^^^^^^^^^^^\n",
      "  File \"/usr/local/lib/python3.11/site-packages/flask/app.py\", line 1517, in full_dispatch_request\n",
      "    rv = self.dispatch_request()\n",
      "         ^^^^^^^^^^^^^^^^^^^^^^^\n",
      "  File \"/usr/local/lib/python3.11/site-packages/flask/app.py\", line 1503, in dispatch_request\n",
      "    return self.ensure_sync(self.view_functions[rule.endpoint])(**req.view_args)\n",
      "           ^^^^^^^^^^^^^^^^^^^^^^^^^^^^^^^^^^^^^^^^^^^^^^^^^^^^^^^^^^^^^^^^^^^^^\n",
      "  File \"/var/folders/2x/1d0r_dyn1snchg_l5_28mb100000gn/T/ipykernel_734/1631882613.py\", line 53, in predict\n",
      "    pred_time, (prediction_class, confidence) = predict_model(model, f\"static/videos/{file_name}\")\n",
      "                                                ^^^^^^^^^^^^^^^^^^^^^^^^^^^^^^^^^^^^^^^^^^^^^^^^^^\n",
      "  File \"/var/folders/2x/1d0r_dyn1snchg_l5_28mb100000gn/T/ipykernel_734/1631882613.py\", line 29, in predict_model\n",
      "    prediction = model.predict(np.array([data_matrix]))\n",
      "                 ^^^^^^^^^^^^^^^^^^^^^^^^^^^^^^^^^^^^^^\n",
      "  File \"/usr/local/lib/python3.11/site-packages/keras/src/utils/traceback_utils.py\", line 70, in error_handler\n",
      "    raise e.with_traceback(filtered_tb) from None\n",
      "  File \"/var/folders/2x/1d0r_dyn1snchg_l5_28mb100000gn/T/__autograph_generated_fileztntsymd.py\", line 18, in tf__predict_function\n",
      "    raise\n",
      "ValueError: in user code:\n",
      "\n",
      "    File \"/usr/local/lib/python3.11/site-packages/keras/src/engine/training.py\", line 2416, in predict_function  *\n",
      "        return step_function(self, iterator)\n",
      "    File \"/usr/local/lib/python3.11/site-packages/keras/src/engine/training.py\", line 2401, in step_function  **\n",
      "        outputs = model.distribute_strategy.run(run_step, args=(data,))\n",
      "    File \"/usr/local/lib/python3.11/site-packages/keras/src/engine/training.py\", line 2389, in run_step  **\n",
      "        outputs = model.predict_step(data)\n",
      "    File \"/usr/local/lib/python3.11/site-packages/keras/src/engine/training.py\", line 2357, in predict_step\n",
      "        return self(x, training=False)\n",
      "    File \"/usr/local/lib/python3.11/site-packages/keras/src/utils/traceback_utils.py\", line 70, in error_handler\n",
      "        raise e.with_traceback(filtered_tb) from None\n",
      "    File \"/usr/local/lib/python3.11/site-packages/keras/src/engine/input_spec.py\", line 235, in assert_input_compatibility\n",
      "        raise ValueError(\n",
      "\n",
      "    ValueError: Exception encountered when calling layer 'model' (type Functional).\n",
      "    \n",
      "    Input 0 of layer \"time_distributed\" is incompatible with the layer: expected ndim=5, found ndim=2. Full shape received: (None, 0)\n",
      "    \n",
      "    Call arguments received by layer 'model' (type Functional):\n",
      "      • inputs=tf.Tensor(shape=(None, 0), dtype=float32)\n",
      "      • training=False\n",
      "      • mask=None\n",
      "\n",
      "OpenCV: Couldn't read video stream from file \"static/videos/pexels-mikhail-nilov-8655759 (1080p).mp4\"\n",
      "127.0.0.1 - - [04/Oct/2023 15:58:19] \"\u001b[35m\u001b[1mPOST /predict HTTP/1.1\u001b[0m\" 500 -\n",
      "INFO:werkzeug:127.0.0.1 - - [04/Oct/2023 15:58:19] \"\u001b[35m\u001b[1mPOST /predict HTTP/1.1\u001b[0m\" 500 -\n",
      "Traceback (most recent call last):\n",
      "  File \"/usr/local/lib/python3.11/site-packages/flask/app.py\", line 2091, in __call__\n",
      "    return self.wsgi_app(environ, start_response)\n",
      "           ^^^^^^^^^^^^^^^^^^^^^^^^^^^^^^^^^^^^^^\n",
      "  File \"/usr/local/lib/python3.11/site-packages/flask/app.py\", line 2076, in wsgi_app\n",
      "    response = self.handle_exception(e)\n",
      "               ^^^^^^^^^^^^^^^^^^^^^^^^\n",
      "  File \"/usr/local/lib/python3.11/site-packages/flask/app.py\", line 2073, in wsgi_app\n",
      "    response = self.full_dispatch_request()\n",
      "               ^^^^^^^^^^^^^^^^^^^^^^^^^^^^\n",
      "  File \"/usr/local/lib/python3.11/site-packages/flask/app.py\", line 1519, in full_dispatch_request\n",
      "    rv = self.handle_user_exception(e)\n",
      "         ^^^^^^^^^^^^^^^^^^^^^^^^^^^^^\n",
      "  File \"/usr/local/lib/python3.11/site-packages/flask/app.py\", line 1517, in full_dispatch_request\n",
      "    rv = self.dispatch_request()\n",
      "         ^^^^^^^^^^^^^^^^^^^^^^^\n",
      "  File \"/usr/local/lib/python3.11/site-packages/flask/app.py\", line 1503, in dispatch_request\n",
      "    return self.ensure_sync(self.view_functions[rule.endpoint])(**req.view_args)\n",
      "           ^^^^^^^^^^^^^^^^^^^^^^^^^^^^^^^^^^^^^^^^^^^^^^^^^^^^^^^^^^^^^^^^^^^^^\n",
      "  File \"/var/folders/2x/1d0r_dyn1snchg_l5_28mb100000gn/T/ipykernel_734/1631882613.py\", line 53, in predict\n",
      "    pred_time, (prediction_class, confidence) = predict_model(model, f\"static/videos/{file_name}\")\n",
      "                                                ^^^^^^^^^^^^^^^^^^^^^^^^^^^^^^^^^^^^^^^^^^^^^^^^^^\n",
      "  File \"/var/folders/2x/1d0r_dyn1snchg_l5_28mb100000gn/T/ipykernel_734/1631882613.py\", line 29, in predict_model\n",
      "    prediction = model.predict(np.array([data_matrix]))\n",
      "                 ^^^^^^^^^^^^^^^^^^^^^^^^^^^^^^^^^^^^^^\n",
      "  File \"/usr/local/lib/python3.11/site-packages/keras/src/utils/traceback_utils.py\", line 70, in error_handler\n",
      "    raise e.with_traceback(filtered_tb) from None\n",
      "  File \"/var/folders/2x/1d0r_dyn1snchg_l5_28mb100000gn/T/__autograph_generated_fileztntsymd.py\", line 18, in tf__predict_function\n",
      "    raise\n",
      "ValueError: in user code:\n",
      "\n",
      "    File \"/usr/local/lib/python3.11/site-packages/keras/src/engine/training.py\", line 2416, in predict_function  *\n",
      "        return step_function(self, iterator)\n",
      "    File \"/usr/local/lib/python3.11/site-packages/keras/src/engine/training.py\", line 2401, in step_function  **\n",
      "        outputs = model.distribute_strategy.run(run_step, args=(data,))\n",
      "    File \"/usr/local/lib/python3.11/site-packages/keras/src/engine/training.py\", line 2389, in run_step  **\n",
      "        outputs = model.predict_step(data)\n",
      "    File \"/usr/local/lib/python3.11/site-packages/keras/src/engine/training.py\", line 2357, in predict_step\n",
      "        return self(x, training=False)\n",
      "    File \"/usr/local/lib/python3.11/site-packages/keras/src/utils/traceback_utils.py\", line 70, in error_handler\n",
      "        raise e.with_traceback(filtered_tb) from None\n",
      "    File \"/usr/local/lib/python3.11/site-packages/keras/src/engine/input_spec.py\", line 235, in assert_input_compatibility\n",
      "        raise ValueError(\n",
      "\n",
      "    ValueError: Exception encountered when calling layer 'model' (type Functional).\n",
      "    \n",
      "    Input 0 of layer \"time_distributed\" is incompatible with the layer: expected ndim=5, found ndim=2. Full shape received: (None, 0)\n",
      "    \n",
      "    Call arguments received by layer 'model' (type Functional):\n",
      "      • inputs=tf.Tensor(shape=(None, 0), dtype=float32)\n",
      "      • training=False\n",
      "      • mask=None\n",
      "\n",
      "OpenCV: Couldn't read video stream from file \"static/videos/pexels-mikhail-nilov-8655759 (1080p).mp4\"\n",
      "127.0.0.1 - - [04/Oct/2023 15:58:25] \"\u001b[35m\u001b[1mPOST /predict HTTP/1.1\u001b[0m\" 500 -\n",
      "INFO:werkzeug:127.0.0.1 - - [04/Oct/2023 15:58:25] \"\u001b[35m\u001b[1mPOST /predict HTTP/1.1\u001b[0m\" 500 -\n",
      "Traceback (most recent call last):\n",
      "  File \"/usr/local/lib/python3.11/site-packages/flask/app.py\", line 2091, in __call__\n",
      "    return self.wsgi_app(environ, start_response)\n",
      "           ^^^^^^^^^^^^^^^^^^^^^^^^^^^^^^^^^^^^^^\n",
      "  File \"/usr/local/lib/python3.11/site-packages/flask/app.py\", line 2076, in wsgi_app\n",
      "    response = self.handle_exception(e)\n",
      "               ^^^^^^^^^^^^^^^^^^^^^^^^\n",
      "  File \"/usr/local/lib/python3.11/site-packages/flask/app.py\", line 2073, in wsgi_app\n",
      "    response = self.full_dispatch_request()\n",
      "               ^^^^^^^^^^^^^^^^^^^^^^^^^^^^\n",
      "  File \"/usr/local/lib/python3.11/site-packages/flask/app.py\", line 1519, in full_dispatch_request\n",
      "    rv = self.handle_user_exception(e)\n",
      "         ^^^^^^^^^^^^^^^^^^^^^^^^^^^^^\n",
      "  File \"/usr/local/lib/python3.11/site-packages/flask/app.py\", line 1517, in full_dispatch_request\n",
      "    rv = self.dispatch_request()\n",
      "         ^^^^^^^^^^^^^^^^^^^^^^^\n",
      "  File \"/usr/local/lib/python3.11/site-packages/flask/app.py\", line 1503, in dispatch_request\n",
      "    return self.ensure_sync(self.view_functions[rule.endpoint])(**req.view_args)\n",
      "           ^^^^^^^^^^^^^^^^^^^^^^^^^^^^^^^^^^^^^^^^^^^^^^^^^^^^^^^^^^^^^^^^^^^^^\n",
      "  File \"/var/folders/2x/1d0r_dyn1snchg_l5_28mb100000gn/T/ipykernel_734/1631882613.py\", line 53, in predict\n",
      "    pred_time, (prediction_class, confidence) = predict_model(model, f\"static/videos/{file_name}\")\n",
      "                                                ^^^^^^^^^^^^^^^^^^^^^^^^^^^^^^^^^^^^^^^^^^^^^^^^^^\n",
      "  File \"/var/folders/2x/1d0r_dyn1snchg_l5_28mb100000gn/T/ipykernel_734/1631882613.py\", line 29, in predict_model\n",
      "    prediction = model.predict(np.array([data_matrix]))\n",
      "                 ^^^^^^^^^^^^^^^^^^^^^^^^^^^^^^^^^^^^^^\n",
      "  File \"/usr/local/lib/python3.11/site-packages/keras/src/utils/traceback_utils.py\", line 70, in error_handler\n",
      "    raise e.with_traceback(filtered_tb) from None\n",
      "  File \"/var/folders/2x/1d0r_dyn1snchg_l5_28mb100000gn/T/__autograph_generated_fileztntsymd.py\", line 18, in tf__predict_function\n",
      "    raise\n",
      "ValueError: in user code:\n",
      "\n",
      "    File \"/usr/local/lib/python3.11/site-packages/keras/src/engine/training.py\", line 2416, in predict_function  *\n",
      "        return step_function(self, iterator)\n",
      "    File \"/usr/local/lib/python3.11/site-packages/keras/src/engine/training.py\", line 2401, in step_function  **\n",
      "        outputs = model.distribute_strategy.run(run_step, args=(data,))\n",
      "    File \"/usr/local/lib/python3.11/site-packages/keras/src/engine/training.py\", line 2389, in run_step  **\n",
      "        outputs = model.predict_step(data)\n",
      "    File \"/usr/local/lib/python3.11/site-packages/keras/src/engine/training.py\", line 2357, in predict_step\n",
      "        return self(x, training=False)\n",
      "    File \"/usr/local/lib/python3.11/site-packages/keras/src/utils/traceback_utils.py\", line 70, in error_handler\n",
      "        raise e.with_traceback(filtered_tb) from None\n",
      "    File \"/usr/local/lib/python3.11/site-packages/keras/src/engine/input_spec.py\", line 235, in assert_input_compatibility\n",
      "        raise ValueError(\n",
      "\n",
      "    ValueError: Exception encountered when calling layer 'model' (type Functional).\n",
      "    \n",
      "    Input 0 of layer \"time_distributed\" is incompatible with the layer: expected ndim=5, found ndim=2. Full shape received: (None, 0)\n",
      "    \n",
      "    Call arguments received by layer 'model' (type Functional):\n",
      "      • inputs=tf.Tensor(shape=(None, 0), dtype=float32)\n",
      "      • training=False\n",
      "      • mask=None\n",
      "\n",
      "OpenCV: Couldn't read video stream from file \"static/videos/pexels-mikhail-nilov-8655759 (1080p).mp4\"\n",
      "127.0.0.1 - - [04/Oct/2023 15:58:25] \"\u001b[35m\u001b[1mPOST /predict HTTP/1.1\u001b[0m\" 500 -\n",
      "INFO:werkzeug:127.0.0.1 - - [04/Oct/2023 15:58:25] \"\u001b[35m\u001b[1mPOST /predict HTTP/1.1\u001b[0m\" 500 -\n",
      "Traceback (most recent call last):\n",
      "  File \"/usr/local/lib/python3.11/site-packages/flask/app.py\", line 2091, in __call__\n",
      "    return self.wsgi_app(environ, start_response)\n",
      "           ^^^^^^^^^^^^^^^^^^^^^^^^^^^^^^^^^^^^^^\n",
      "  File \"/usr/local/lib/python3.11/site-packages/flask/app.py\", line 2076, in wsgi_app\n",
      "    response = self.handle_exception(e)\n",
      "               ^^^^^^^^^^^^^^^^^^^^^^^^\n",
      "  File \"/usr/local/lib/python3.11/site-packages/flask/app.py\", line 2073, in wsgi_app\n",
      "    response = self.full_dispatch_request()\n",
      "               ^^^^^^^^^^^^^^^^^^^^^^^^^^^^\n",
      "  File \"/usr/local/lib/python3.11/site-packages/flask/app.py\", line 1519, in full_dispatch_request\n",
      "    rv = self.handle_user_exception(e)\n",
      "         ^^^^^^^^^^^^^^^^^^^^^^^^^^^^^\n",
      "  File \"/usr/local/lib/python3.11/site-packages/flask/app.py\", line 1517, in full_dispatch_request\n",
      "    rv = self.dispatch_request()\n",
      "         ^^^^^^^^^^^^^^^^^^^^^^^\n",
      "  File \"/usr/local/lib/python3.11/site-packages/flask/app.py\", line 1503, in dispatch_request\n",
      "    return self.ensure_sync(self.view_functions[rule.endpoint])(**req.view_args)\n",
      "           ^^^^^^^^^^^^^^^^^^^^^^^^^^^^^^^^^^^^^^^^^^^^^^^^^^^^^^^^^^^^^^^^^^^^^\n",
      "  File \"/var/folders/2x/1d0r_dyn1snchg_l5_28mb100000gn/T/ipykernel_734/1631882613.py\", line 53, in predict\n",
      "    pred_time, (prediction_class, confidence) = predict_model(model, f\"static/videos/{file_name}\")\n",
      "                                                ^^^^^^^^^^^^^^^^^^^^^^^^^^^^^^^^^^^^^^^^^^^^^^^^^^\n",
      "  File \"/var/folders/2x/1d0r_dyn1snchg_l5_28mb100000gn/T/ipykernel_734/1631882613.py\", line 29, in predict_model\n",
      "    prediction = model.predict(np.array([data_matrix]))\n",
      "                 ^^^^^^^^^^^^^^^^^^^^^^^^^^^^^^^^^^^^^^\n",
      "  File \"/usr/local/lib/python3.11/site-packages/keras/src/utils/traceback_utils.py\", line 70, in error_handler\n",
      "    raise e.with_traceback(filtered_tb) from None\n",
      "  File \"/var/folders/2x/1d0r_dyn1snchg_l5_28mb100000gn/T/__autograph_generated_fileztntsymd.py\", line 18, in tf__predict_function\n",
      "    raise\n",
      "ValueError: in user code:\n",
      "\n",
      "    File \"/usr/local/lib/python3.11/site-packages/keras/src/engine/training.py\", line 2416, in predict_function  *\n",
      "        return step_function(self, iterator)\n",
      "    File \"/usr/local/lib/python3.11/site-packages/keras/src/engine/training.py\", line 2401, in step_function  **\n",
      "        outputs = model.distribute_strategy.run(run_step, args=(data,))\n",
      "    File \"/usr/local/lib/python3.11/site-packages/keras/src/engine/training.py\", line 2389, in run_step  **\n",
      "        outputs = model.predict_step(data)\n",
      "    File \"/usr/local/lib/python3.11/site-packages/keras/src/engine/training.py\", line 2357, in predict_step\n",
      "        return self(x, training=False)\n",
      "    File \"/usr/local/lib/python3.11/site-packages/keras/src/utils/traceback_utils.py\", line 70, in error_handler\n",
      "        raise e.with_traceback(filtered_tb) from None\n",
      "    File \"/usr/local/lib/python3.11/site-packages/keras/src/engine/input_spec.py\", line 235, in assert_input_compatibility\n",
      "        raise ValueError(\n",
      "\n",
      "    ValueError: Exception encountered when calling layer 'model' (type Functional).\n",
      "    \n",
      "    Input 0 of layer \"time_distributed\" is incompatible with the layer: expected ndim=5, found ndim=2. Full shape received: (None, 0)\n",
      "    \n",
      "    Call arguments received by layer 'model' (type Functional):\n",
      "      • inputs=tf.Tensor(shape=(None, 0), dtype=float32)\n",
      "      • training=False\n",
      "      • mask=None\n",
      "\n",
      "OpenCV: Couldn't read video stream from file \"static/videos/pexels-mikhail-nilov-8655759 (1080p).mp4\"\n",
      "127.0.0.1 - - [04/Oct/2023 15:58:26] \"\u001b[35m\u001b[1mPOST /predict HTTP/1.1\u001b[0m\" 500 -\n",
      "INFO:werkzeug:127.0.0.1 - - [04/Oct/2023 15:58:26] \"\u001b[35m\u001b[1mPOST /predict HTTP/1.1\u001b[0m\" 500 -\n",
      "Traceback (most recent call last):\n",
      "  File \"/usr/local/lib/python3.11/site-packages/flask/app.py\", line 2091, in __call__\n",
      "    return self.wsgi_app(environ, start_response)\n",
      "           ^^^^^^^^^^^^^^^^^^^^^^^^^^^^^^^^^^^^^^\n",
      "  File \"/usr/local/lib/python3.11/site-packages/flask/app.py\", line 2076, in wsgi_app\n",
      "    response = self.handle_exception(e)\n",
      "               ^^^^^^^^^^^^^^^^^^^^^^^^\n",
      "  File \"/usr/local/lib/python3.11/site-packages/flask/app.py\", line 2073, in wsgi_app\n",
      "    response = self.full_dispatch_request()\n",
      "               ^^^^^^^^^^^^^^^^^^^^^^^^^^^^\n",
      "  File \"/usr/local/lib/python3.11/site-packages/flask/app.py\", line 1519, in full_dispatch_request\n",
      "    rv = self.handle_user_exception(e)\n",
      "         ^^^^^^^^^^^^^^^^^^^^^^^^^^^^^\n",
      "  File \"/usr/local/lib/python3.11/site-packages/flask/app.py\", line 1517, in full_dispatch_request\n",
      "    rv = self.dispatch_request()\n",
      "         ^^^^^^^^^^^^^^^^^^^^^^^\n",
      "  File \"/usr/local/lib/python3.11/site-packages/flask/app.py\", line 1503, in dispatch_request\n",
      "    return self.ensure_sync(self.view_functions[rule.endpoint])(**req.view_args)\n",
      "           ^^^^^^^^^^^^^^^^^^^^^^^^^^^^^^^^^^^^^^^^^^^^^^^^^^^^^^^^^^^^^^^^^^^^^\n",
      "  File \"/var/folders/2x/1d0r_dyn1snchg_l5_28mb100000gn/T/ipykernel_734/1631882613.py\", line 53, in predict\n",
      "    pred_time, (prediction_class, confidence) = predict_model(model, f\"static/videos/{file_name}\")\n",
      "                                                ^^^^^^^^^^^^^^^^^^^^^^^^^^^^^^^^^^^^^^^^^^^^^^^^^^\n",
      "  File \"/var/folders/2x/1d0r_dyn1snchg_l5_28mb100000gn/T/ipykernel_734/1631882613.py\", line 29, in predict_model\n",
      "    prediction = model.predict(np.array([data_matrix]))\n",
      "                 ^^^^^^^^^^^^^^^^^^^^^^^^^^^^^^^^^^^^^^\n",
      "  File \"/usr/local/lib/python3.11/site-packages/keras/src/utils/traceback_utils.py\", line 70, in error_handler\n",
      "    raise e.with_traceback(filtered_tb) from None\n",
      "  File \"/var/folders/2x/1d0r_dyn1snchg_l5_28mb100000gn/T/__autograph_generated_fileztntsymd.py\", line 18, in tf__predict_function\n",
      "    raise\n",
      "ValueError: in user code:\n",
      "\n",
      "    File \"/usr/local/lib/python3.11/site-packages/keras/src/engine/training.py\", line 2416, in predict_function  *\n",
      "        return step_function(self, iterator)\n",
      "    File \"/usr/local/lib/python3.11/site-packages/keras/src/engine/training.py\", line 2401, in step_function  **\n",
      "        outputs = model.distribute_strategy.run(run_step, args=(data,))\n",
      "    File \"/usr/local/lib/python3.11/site-packages/keras/src/engine/training.py\", line 2389, in run_step  **\n",
      "        outputs = model.predict_step(data)\n",
      "    File \"/usr/local/lib/python3.11/site-packages/keras/src/engine/training.py\", line 2357, in predict_step\n",
      "        return self(x, training=False)\n",
      "    File \"/usr/local/lib/python3.11/site-packages/keras/src/utils/traceback_utils.py\", line 70, in error_handler\n",
      "        raise e.with_traceback(filtered_tb) from None\n",
      "    File \"/usr/local/lib/python3.11/site-packages/keras/src/engine/input_spec.py\", line 235, in assert_input_compatibility\n",
      "        raise ValueError(\n",
      "\n",
      "    ValueError: Exception encountered when calling layer 'model' (type Functional).\n",
      "    \n",
      "    Input 0 of layer \"time_distributed\" is incompatible with the layer: expected ndim=5, found ndim=2. Full shape received: (None, 0)\n",
      "    \n",
      "    Call arguments received by layer 'model' (type Functional):\n",
      "      • inputs=tf.Tensor(shape=(None, 0), dtype=float32)\n",
      "      • training=False\n",
      "      • mask=None\n",
      "\n",
      "OpenCV: Couldn't read video stream from file \"static/videos/pexels-mikhail-nilov-8655759 (1080p).mp4\"\n",
      "127.0.0.1 - - [04/Oct/2023 15:58:26] \"\u001b[35m\u001b[1mPOST /predict HTTP/1.1\u001b[0m\" 500 -\n",
      "INFO:werkzeug:127.0.0.1 - - [04/Oct/2023 15:58:26] \"\u001b[35m\u001b[1mPOST /predict HTTP/1.1\u001b[0m\" 500 -\n",
      "Traceback (most recent call last):\n",
      "  File \"/usr/local/lib/python3.11/site-packages/flask/app.py\", line 2091, in __call__\n",
      "    return self.wsgi_app(environ, start_response)\n",
      "           ^^^^^^^^^^^^^^^^^^^^^^^^^^^^^^^^^^^^^^\n",
      "  File \"/usr/local/lib/python3.11/site-packages/flask/app.py\", line 2076, in wsgi_app\n",
      "    response = self.handle_exception(e)\n",
      "               ^^^^^^^^^^^^^^^^^^^^^^^^\n",
      "  File \"/usr/local/lib/python3.11/site-packages/flask/app.py\", line 2073, in wsgi_app\n",
      "    response = self.full_dispatch_request()\n",
      "               ^^^^^^^^^^^^^^^^^^^^^^^^^^^^\n",
      "  File \"/usr/local/lib/python3.11/site-packages/flask/app.py\", line 1519, in full_dispatch_request\n",
      "    rv = self.handle_user_exception(e)\n",
      "         ^^^^^^^^^^^^^^^^^^^^^^^^^^^^^\n",
      "  File \"/usr/local/lib/python3.11/site-packages/flask/app.py\", line 1517, in full_dispatch_request\n",
      "    rv = self.dispatch_request()\n",
      "         ^^^^^^^^^^^^^^^^^^^^^^^\n",
      "  File \"/usr/local/lib/python3.11/site-packages/flask/app.py\", line 1503, in dispatch_request\n",
      "    return self.ensure_sync(self.view_functions[rule.endpoint])(**req.view_args)\n",
      "           ^^^^^^^^^^^^^^^^^^^^^^^^^^^^^^^^^^^^^^^^^^^^^^^^^^^^^^^^^^^^^^^^^^^^^\n",
      "  File \"/var/folders/2x/1d0r_dyn1snchg_l5_28mb100000gn/T/ipykernel_734/1631882613.py\", line 53, in predict\n",
      "    pred_time, (prediction_class, confidence) = predict_model(model, f\"static/videos/{file_name}\")\n",
      "                                                ^^^^^^^^^^^^^^^^^^^^^^^^^^^^^^^^^^^^^^^^^^^^^^^^^^\n",
      "  File \"/var/folders/2x/1d0r_dyn1snchg_l5_28mb100000gn/T/ipykernel_734/1631882613.py\", line 29, in predict_model\n",
      "    prediction = model.predict(np.array([data_matrix]))\n",
      "                 ^^^^^^^^^^^^^^^^^^^^^^^^^^^^^^^^^^^^^^\n",
      "  File \"/usr/local/lib/python3.11/site-packages/keras/src/utils/traceback_utils.py\", line 70, in error_handler\n",
      "    raise e.with_traceback(filtered_tb) from None\n",
      "  File \"/var/folders/2x/1d0r_dyn1snchg_l5_28mb100000gn/T/__autograph_generated_fileztntsymd.py\", line 18, in tf__predict_function\n",
      "    raise\n",
      "ValueError: in user code:\n",
      "\n",
      "    File \"/usr/local/lib/python3.11/site-packages/keras/src/engine/training.py\", line 2416, in predict_function  *\n",
      "        return step_function(self, iterator)\n",
      "    File \"/usr/local/lib/python3.11/site-packages/keras/src/engine/training.py\", line 2401, in step_function  **\n",
      "        outputs = model.distribute_strategy.run(run_step, args=(data,))\n",
      "    File \"/usr/local/lib/python3.11/site-packages/keras/src/engine/training.py\", line 2389, in run_step  **\n",
      "        outputs = model.predict_step(data)\n",
      "    File \"/usr/local/lib/python3.11/site-packages/keras/src/engine/training.py\", line 2357, in predict_step\n",
      "        return self(x, training=False)\n",
      "    File \"/usr/local/lib/python3.11/site-packages/keras/src/utils/traceback_utils.py\", line 70, in error_handler\n",
      "        raise e.with_traceback(filtered_tb) from None\n",
      "    File \"/usr/local/lib/python3.11/site-packages/keras/src/engine/input_spec.py\", line 235, in assert_input_compatibility\n",
      "        raise ValueError(\n",
      "\n",
      "    ValueError: Exception encountered when calling layer 'model' (type Functional).\n",
      "    \n",
      "    Input 0 of layer \"time_distributed\" is incompatible with the layer: expected ndim=5, found ndim=2. Full shape received: (None, 0)\n",
      "    \n",
      "    Call arguments received by layer 'model' (type Functional):\n",
      "      • inputs=tf.Tensor(shape=(None, 0), dtype=float32)\n",
      "      • training=False\n",
      "      • mask=None\n",
      "\n",
      "127.0.0.1 - - [04/Oct/2023 15:58:59] \"\u001b[33mGET /videos/v_Spinning_01.xml HTTP/1.1\u001b[0m\" 404 -\n",
      "INFO:werkzeug:127.0.0.1 - - [04/Oct/2023 15:58:59] \"\u001b[33mGET /videos/v_Spinning_01.xml HTTP/1.1\u001b[0m\" 404 -\n",
      "127.0.0.1 - - [04/Oct/2023 15:59:00] \"POST /predict HTTP/1.1\" 200 -\n",
      "INFO:werkzeug:127.0.0.1 - - [04/Oct/2023 15:59:00] \"POST /predict HTTP/1.1\" 200 -\n",
      "127.0.0.1 - - [04/Oct/2023 15:59:01] \"POST /predict HTTP/1.1\" 200 -\n",
      "INFO:werkzeug:127.0.0.1 - - [04/Oct/2023 15:59:01] \"POST /predict HTTP/1.1\" 200 -\n",
      "127.0.0.1 - - [04/Oct/2023 15:59:01] \"POST /predict HTTP/1.1\" 200 -\n",
      "INFO:werkzeug:127.0.0.1 - - [04/Oct/2023 15:59:01] \"POST /predict HTTP/1.1\" 200 -\n",
      "127.0.0.1 - - [04/Oct/2023 15:59:01] \"POST /predict HTTP/1.1\" 200 -\n",
      "INFO:werkzeug:127.0.0.1 - - [04/Oct/2023 15:59:01] \"POST /predict HTTP/1.1\" 200 -\n",
      "127.0.0.1 - - [04/Oct/2023 15:59:02] \"POST /predict HTTP/1.1\" 200 -\n",
      "INFO:werkzeug:127.0.0.1 - - [04/Oct/2023 15:59:02] \"POST /predict HTTP/1.1\" 200 -\n",
      "127.0.0.1 - - [04/Oct/2023 15:59:02] \"POST /predict HTTP/1.1\" 200 -\n",
      "INFO:werkzeug:127.0.0.1 - - [04/Oct/2023 15:59:02] \"POST /predict HTTP/1.1\" 200 -\n",
      "127.0.0.1 - - [04/Oct/2023 15:59:02] \"POST /predict HTTP/1.1\" 200 -\n",
      "INFO:werkzeug:127.0.0.1 - - [04/Oct/2023 15:59:02] \"POST /predict HTTP/1.1\" 200 -\n",
      "127.0.0.1 - - [04/Oct/2023 15:59:57] \"\u001b[33mGET /videos/video1_control.mp4 HTTP/1.1\u001b[0m\" 404 -\n",
      "INFO:werkzeug:127.0.0.1 - - [04/Oct/2023 15:59:57] \"\u001b[33mGET /videos/video1_control.mp4 HTTP/1.1\u001b[0m\" 404 -\n",
      "OpenCV: Couldn't read video stream from file \"static/videos/video1_control.mp4\"\n",
      "127.0.0.1 - - [04/Oct/2023 15:59:59] \"\u001b[35m\u001b[1mPOST /predict HTTP/1.1\u001b[0m\" 500 -\n",
      "INFO:werkzeug:127.0.0.1 - - [04/Oct/2023 15:59:59] \"\u001b[35m\u001b[1mPOST /predict HTTP/1.1\u001b[0m\" 500 -\n",
      "Traceback (most recent call last):\n",
      "  File \"/usr/local/lib/python3.11/site-packages/flask/app.py\", line 2091, in __call__\n",
      "    return self.wsgi_app(environ, start_response)\n",
      "           ^^^^^^^^^^^^^^^^^^^^^^^^^^^^^^^^^^^^^^\n",
      "  File \"/usr/local/lib/python3.11/site-packages/flask/app.py\", line 2076, in wsgi_app\n",
      "    response = self.handle_exception(e)\n",
      "               ^^^^^^^^^^^^^^^^^^^^^^^^\n",
      "  File \"/usr/local/lib/python3.11/site-packages/flask/app.py\", line 2073, in wsgi_app\n",
      "    response = self.full_dispatch_request()\n",
      "               ^^^^^^^^^^^^^^^^^^^^^^^^^^^^\n",
      "  File \"/usr/local/lib/python3.11/site-packages/flask/app.py\", line 1519, in full_dispatch_request\n",
      "    rv = self.handle_user_exception(e)\n",
      "         ^^^^^^^^^^^^^^^^^^^^^^^^^^^^^\n",
      "  File \"/usr/local/lib/python3.11/site-packages/flask/app.py\", line 1517, in full_dispatch_request\n",
      "    rv = self.dispatch_request()\n",
      "         ^^^^^^^^^^^^^^^^^^^^^^^\n",
      "  File \"/usr/local/lib/python3.11/site-packages/flask/app.py\", line 1503, in dispatch_request\n",
      "    return self.ensure_sync(self.view_functions[rule.endpoint])(**req.view_args)\n",
      "           ^^^^^^^^^^^^^^^^^^^^^^^^^^^^^^^^^^^^^^^^^^^^^^^^^^^^^^^^^^^^^^^^^^^^^\n",
      "  File \"/var/folders/2x/1d0r_dyn1snchg_l5_28mb100000gn/T/ipykernel_734/1631882613.py\", line 53, in predict\n",
      "    pred_time, (prediction_class, confidence) = predict_model(model, f\"static/videos/{file_name}\")\n",
      "                                                ^^^^^^^^^^^^^^^^^^^^^^^^^^^^^^^^^^^^^^^^^^^^^^^^^^\n",
      "  File \"/var/folders/2x/1d0r_dyn1snchg_l5_28mb100000gn/T/ipykernel_734/1631882613.py\", line 29, in predict_model\n",
      "    prediction = model.predict(np.array([data_matrix]))\n",
      "                 ^^^^^^^^^^^^^^^^^^^^^^^^^^^^^^^^^^^^^^\n",
      "  File \"/usr/local/lib/python3.11/site-packages/keras/src/utils/traceback_utils.py\", line 70, in error_handler\n",
      "    raise e.with_traceback(filtered_tb) from None\n",
      "  File \"/var/folders/2x/1d0r_dyn1snchg_l5_28mb100000gn/T/__autograph_generated_fileztntsymd.py\", line 18, in tf__predict_function\n",
      "    raise\n",
      "ValueError: in user code:\n",
      "\n",
      "    File \"/usr/local/lib/python3.11/site-packages/keras/src/engine/training.py\", line 2416, in predict_function  *\n",
      "        return step_function(self, iterator)\n",
      "    File \"/usr/local/lib/python3.11/site-packages/keras/src/engine/training.py\", line 2401, in step_function  **\n",
      "        outputs = model.distribute_strategy.run(run_step, args=(data,))\n",
      "    File \"/usr/local/lib/python3.11/site-packages/keras/src/engine/training.py\", line 2389, in run_step  **\n",
      "        outputs = model.predict_step(data)\n",
      "    File \"/usr/local/lib/python3.11/site-packages/keras/src/engine/training.py\", line 2357, in predict_step\n",
      "        return self(x, training=False)\n",
      "    File \"/usr/local/lib/python3.11/site-packages/keras/src/utils/traceback_utils.py\", line 70, in error_handler\n",
      "        raise e.with_traceback(filtered_tb) from None\n",
      "    File \"/usr/local/lib/python3.11/site-packages/keras/src/engine/input_spec.py\", line 235, in assert_input_compatibility\n",
      "        raise ValueError(\n",
      "\n",
      "    ValueError: Exception encountered when calling layer 'model' (type Functional).\n",
      "    \n",
      "    Input 0 of layer \"time_distributed\" is incompatible with the layer: expected ndim=5, found ndim=2. Full shape received: (None, 0)\n",
      "    \n",
      "    Call arguments received by layer 'model' (type Functional):\n",
      "      • inputs=tf.Tensor(shape=(None, 0), dtype=float32)\n",
      "      • training=False\n",
      "      • mask=None\n",
      "\n",
      "OpenCV: Couldn't read video stream from file \"static/videos/video1_control.mp4\"\n",
      "127.0.0.1 - - [04/Oct/2023 16:00:00] \"\u001b[35m\u001b[1mPOST /predict HTTP/1.1\u001b[0m\" 500 -\n",
      "INFO:werkzeug:127.0.0.1 - - [04/Oct/2023 16:00:00] \"\u001b[35m\u001b[1mPOST /predict HTTP/1.1\u001b[0m\" 500 -\n",
      "Traceback (most recent call last):\n",
      "  File \"/usr/local/lib/python3.11/site-packages/flask/app.py\", line 2091, in __call__\n",
      "    return self.wsgi_app(environ, start_response)\n",
      "           ^^^^^^^^^^^^^^^^^^^^^^^^^^^^^^^^^^^^^^\n",
      "  File \"/usr/local/lib/python3.11/site-packages/flask/app.py\", line 2076, in wsgi_app\n",
      "    response = self.handle_exception(e)\n",
      "               ^^^^^^^^^^^^^^^^^^^^^^^^\n",
      "  File \"/usr/local/lib/python3.11/site-packages/flask/app.py\", line 2073, in wsgi_app\n",
      "    response = self.full_dispatch_request()\n",
      "               ^^^^^^^^^^^^^^^^^^^^^^^^^^^^\n",
      "  File \"/usr/local/lib/python3.11/site-packages/flask/app.py\", line 1519, in full_dispatch_request\n",
      "    rv = self.handle_user_exception(e)\n",
      "         ^^^^^^^^^^^^^^^^^^^^^^^^^^^^^\n",
      "  File \"/usr/local/lib/python3.11/site-packages/flask/app.py\", line 1517, in full_dispatch_request\n",
      "    rv = self.dispatch_request()\n",
      "         ^^^^^^^^^^^^^^^^^^^^^^^\n",
      "  File \"/usr/local/lib/python3.11/site-packages/flask/app.py\", line 1503, in dispatch_request\n",
      "    return self.ensure_sync(self.view_functions[rule.endpoint])(**req.view_args)\n",
      "           ^^^^^^^^^^^^^^^^^^^^^^^^^^^^^^^^^^^^^^^^^^^^^^^^^^^^^^^^^^^^^^^^^^^^^\n",
      "  File \"/var/folders/2x/1d0r_dyn1snchg_l5_28mb100000gn/T/ipykernel_734/1631882613.py\", line 53, in predict\n",
      "    pred_time, (prediction_class, confidence) = predict_model(model, f\"static/videos/{file_name}\")\n",
      "                                                ^^^^^^^^^^^^^^^^^^^^^^^^^^^^^^^^^^^^^^^^^^^^^^^^^^\n",
      "  File \"/var/folders/2x/1d0r_dyn1snchg_l5_28mb100000gn/T/ipykernel_734/1631882613.py\", line 29, in predict_model\n",
      "    prediction = model.predict(np.array([data_matrix]))\n",
      "                 ^^^^^^^^^^^^^^^^^^^^^^^^^^^^^^^^^^^^^^\n",
      "  File \"/usr/local/lib/python3.11/site-packages/keras/src/utils/traceback_utils.py\", line 70, in error_handler\n",
      "    raise e.with_traceback(filtered_tb) from None\n",
      "  File \"/var/folders/2x/1d0r_dyn1snchg_l5_28mb100000gn/T/__autograph_generated_fileztntsymd.py\", line 18, in tf__predict_function\n",
      "    raise\n",
      "ValueError: in user code:\n",
      "\n",
      "    File \"/usr/local/lib/python3.11/site-packages/keras/src/engine/training.py\", line 2416, in predict_function  *\n",
      "        return step_function(self, iterator)\n",
      "    File \"/usr/local/lib/python3.11/site-packages/keras/src/engine/training.py\", line 2401, in step_function  **\n",
      "        outputs = model.distribute_strategy.run(run_step, args=(data,))\n",
      "    File \"/usr/local/lib/python3.11/site-packages/keras/src/engine/training.py\", line 2389, in run_step  **\n",
      "        outputs = model.predict_step(data)\n",
      "    File \"/usr/local/lib/python3.11/site-packages/keras/src/engine/training.py\", line 2357, in predict_step\n",
      "        return self(x, training=False)\n",
      "    File \"/usr/local/lib/python3.11/site-packages/keras/src/utils/traceback_utils.py\", line 70, in error_handler\n",
      "        raise e.with_traceback(filtered_tb) from None\n",
      "    File \"/usr/local/lib/python3.11/site-packages/keras/src/engine/input_spec.py\", line 235, in assert_input_compatibility\n",
      "        raise ValueError(\n",
      "\n",
      "    ValueError: Exception encountered when calling layer 'model' (type Functional).\n",
      "    \n",
      "    Input 0 of layer \"time_distributed\" is incompatible with the layer: expected ndim=5, found ndim=2. Full shape received: (None, 0)\n",
      "    \n",
      "    Call arguments received by layer 'model' (type Functional):\n",
      "      • inputs=tf.Tensor(shape=(None, 0), dtype=float32)\n",
      "      • training=False\n",
      "      • mask=None\n",
      "\n",
      "OpenCV: Couldn't read video stream from file \"static/videos/video1_control.mp4\"\n",
      "127.0.0.1 - - [04/Oct/2023 16:00:00] \"\u001b[35m\u001b[1mPOST /predict HTTP/1.1\u001b[0m\" 500 -\n",
      "INFO:werkzeug:127.0.0.1 - - [04/Oct/2023 16:00:00] \"\u001b[35m\u001b[1mPOST /predict HTTP/1.1\u001b[0m\" 500 -\n",
      "Traceback (most recent call last):\n",
      "  File \"/usr/local/lib/python3.11/site-packages/flask/app.py\", line 2091, in __call__\n",
      "    return self.wsgi_app(environ, start_response)\n",
      "           ^^^^^^^^^^^^^^^^^^^^^^^^^^^^^^^^^^^^^^\n",
      "  File \"/usr/local/lib/python3.11/site-packages/flask/app.py\", line 2076, in wsgi_app\n",
      "    response = self.handle_exception(e)\n",
      "               ^^^^^^^^^^^^^^^^^^^^^^^^\n",
      "  File \"/usr/local/lib/python3.11/site-packages/flask/app.py\", line 2073, in wsgi_app\n",
      "    response = self.full_dispatch_request()\n",
      "               ^^^^^^^^^^^^^^^^^^^^^^^^^^^^\n",
      "  File \"/usr/local/lib/python3.11/site-packages/flask/app.py\", line 1519, in full_dispatch_request\n",
      "    rv = self.handle_user_exception(e)\n",
      "         ^^^^^^^^^^^^^^^^^^^^^^^^^^^^^\n",
      "  File \"/usr/local/lib/python3.11/site-packages/flask/app.py\", line 1517, in full_dispatch_request\n",
      "    rv = self.dispatch_request()\n",
      "         ^^^^^^^^^^^^^^^^^^^^^^^\n",
      "  File \"/usr/local/lib/python3.11/site-packages/flask/app.py\", line 1503, in dispatch_request\n",
      "    return self.ensure_sync(self.view_functions[rule.endpoint])(**req.view_args)\n",
      "           ^^^^^^^^^^^^^^^^^^^^^^^^^^^^^^^^^^^^^^^^^^^^^^^^^^^^^^^^^^^^^^^^^^^^^\n",
      "  File \"/var/folders/2x/1d0r_dyn1snchg_l5_28mb100000gn/T/ipykernel_734/1631882613.py\", line 53, in predict\n",
      "    pred_time, (prediction_class, confidence) = predict_model(model, f\"static/videos/{file_name}\")\n",
      "                                                ^^^^^^^^^^^^^^^^^^^^^^^^^^^^^^^^^^^^^^^^^^^^^^^^^^\n",
      "  File \"/var/folders/2x/1d0r_dyn1snchg_l5_28mb100000gn/T/ipykernel_734/1631882613.py\", line 29, in predict_model\n",
      "    prediction = model.predict(np.array([data_matrix]))\n",
      "                 ^^^^^^^^^^^^^^^^^^^^^^^^^^^^^^^^^^^^^^\n",
      "  File \"/usr/local/lib/python3.11/site-packages/keras/src/utils/traceback_utils.py\", line 70, in error_handler\n",
      "    raise e.with_traceback(filtered_tb) from None\n",
      "  File \"/var/folders/2x/1d0r_dyn1snchg_l5_28mb100000gn/T/__autograph_generated_fileztntsymd.py\", line 18, in tf__predict_function\n",
      "    raise\n",
      "ValueError: in user code:\n",
      "\n",
      "    File \"/usr/local/lib/python3.11/site-packages/keras/src/engine/training.py\", line 2416, in predict_function  *\n",
      "        return step_function(self, iterator)\n",
      "    File \"/usr/local/lib/python3.11/site-packages/keras/src/engine/training.py\", line 2401, in step_function  **\n",
      "        outputs = model.distribute_strategy.run(run_step, args=(data,))\n",
      "    File \"/usr/local/lib/python3.11/site-packages/keras/src/engine/training.py\", line 2389, in run_step  **\n",
      "        outputs = model.predict_step(data)\n",
      "    File \"/usr/local/lib/python3.11/site-packages/keras/src/engine/training.py\", line 2357, in predict_step\n",
      "        return self(x, training=False)\n",
      "    File \"/usr/local/lib/python3.11/site-packages/keras/src/utils/traceback_utils.py\", line 70, in error_handler\n",
      "        raise e.with_traceback(filtered_tb) from None\n",
      "    File \"/usr/local/lib/python3.11/site-packages/keras/src/engine/input_spec.py\", line 235, in assert_input_compatibility\n",
      "        raise ValueError(\n",
      "\n",
      "    ValueError: Exception encountered when calling layer 'model' (type Functional).\n",
      "    \n",
      "    Input 0 of layer \"time_distributed\" is incompatible with the layer: expected ndim=5, found ndim=2. Full shape received: (None, 0)\n",
      "    \n",
      "    Call arguments received by layer 'model' (type Functional):\n",
      "      • inputs=tf.Tensor(shape=(None, 0), dtype=float32)\n",
      "      • training=False\n",
      "      • mask=None\n",
      "\n",
      "127.0.0.1 - - [04/Oct/2023 16:00:01] \"GET / HTTP/1.1\" 200 -\n",
      "INFO:werkzeug:127.0.0.1 - - [04/Oct/2023 16:00:01] \"GET / HTTP/1.1\" 200 -\n",
      "127.0.0.1 - - [04/Oct/2023 16:00:06] \"\u001b[33mGET /videos/video1_control.mp4 HTTP/1.1\u001b[0m\" 404 -\n",
      "INFO:werkzeug:127.0.0.1 - - [04/Oct/2023 16:00:06] \"\u001b[33mGET /videos/video1_control.mp4 HTTP/1.1\u001b[0m\" 404 -\n",
      "OpenCV: Couldn't read video stream from file \"static/videos/video1_control.mp4\"\n",
      "127.0.0.1 - - [04/Oct/2023 16:00:07] \"\u001b[35m\u001b[1mPOST /predict HTTP/1.1\u001b[0m\" 500 -\n",
      "INFO:werkzeug:127.0.0.1 - - [04/Oct/2023 16:00:07] \"\u001b[35m\u001b[1mPOST /predict HTTP/1.1\u001b[0m\" 500 -\n",
      "Traceback (most recent call last):\n",
      "  File \"/usr/local/lib/python3.11/site-packages/flask/app.py\", line 2091, in __call__\n",
      "    return self.wsgi_app(environ, start_response)\n",
      "           ^^^^^^^^^^^^^^^^^^^^^^^^^^^^^^^^^^^^^^\n",
      "  File \"/usr/local/lib/python3.11/site-packages/flask/app.py\", line 2076, in wsgi_app\n",
      "    response = self.handle_exception(e)\n",
      "               ^^^^^^^^^^^^^^^^^^^^^^^^\n",
      "  File \"/usr/local/lib/python3.11/site-packages/flask/app.py\", line 2073, in wsgi_app\n",
      "    response = self.full_dispatch_request()\n",
      "               ^^^^^^^^^^^^^^^^^^^^^^^^^^^^\n",
      "  File \"/usr/local/lib/python3.11/site-packages/flask/app.py\", line 1519, in full_dispatch_request\n",
      "    rv = self.handle_user_exception(e)\n",
      "         ^^^^^^^^^^^^^^^^^^^^^^^^^^^^^\n",
      "  File \"/usr/local/lib/python3.11/site-packages/flask/app.py\", line 1517, in full_dispatch_request\n",
      "    rv = self.dispatch_request()\n",
      "         ^^^^^^^^^^^^^^^^^^^^^^^\n",
      "  File \"/usr/local/lib/python3.11/site-packages/flask/app.py\", line 1503, in dispatch_request\n",
      "    return self.ensure_sync(self.view_functions[rule.endpoint])(**req.view_args)\n",
      "           ^^^^^^^^^^^^^^^^^^^^^^^^^^^^^^^^^^^^^^^^^^^^^^^^^^^^^^^^^^^^^^^^^^^^^\n",
      "  File \"/var/folders/2x/1d0r_dyn1snchg_l5_28mb100000gn/T/ipykernel_734/1631882613.py\", line 53, in predict\n",
      "    pred_time, (prediction_class, confidence) = predict_model(model, f\"static/videos/{file_name}\")\n",
      "                                                ^^^^^^^^^^^^^^^^^^^^^^^^^^^^^^^^^^^^^^^^^^^^^^^^^^\n",
      "  File \"/var/folders/2x/1d0r_dyn1snchg_l5_28mb100000gn/T/ipykernel_734/1631882613.py\", line 29, in predict_model\n",
      "    prediction = model.predict(np.array([data_matrix]))\n",
      "                 ^^^^^^^^^^^^^^^^^^^^^^^^^^^^^^^^^^^^^^\n",
      "  File \"/usr/local/lib/python3.11/site-packages/keras/src/utils/traceback_utils.py\", line 70, in error_handler\n",
      "    raise e.with_traceback(filtered_tb) from None\n",
      "  File \"/var/folders/2x/1d0r_dyn1snchg_l5_28mb100000gn/T/__autograph_generated_fileztntsymd.py\", line 18, in tf__predict_function\n",
      "    raise\n",
      "ValueError: in user code:\n",
      "\n",
      "    File \"/usr/local/lib/python3.11/site-packages/keras/src/engine/training.py\", line 2416, in predict_function  *\n",
      "        return step_function(self, iterator)\n",
      "    File \"/usr/local/lib/python3.11/site-packages/keras/src/engine/training.py\", line 2401, in step_function  **\n",
      "        outputs = model.distribute_strategy.run(run_step, args=(data,))\n",
      "    File \"/usr/local/lib/python3.11/site-packages/keras/src/engine/training.py\", line 2389, in run_step  **\n",
      "        outputs = model.predict_step(data)\n",
      "    File \"/usr/local/lib/python3.11/site-packages/keras/src/engine/training.py\", line 2357, in predict_step\n",
      "        return self(x, training=False)\n",
      "    File \"/usr/local/lib/python3.11/site-packages/keras/src/utils/traceback_utils.py\", line 70, in error_handler\n",
      "        raise e.with_traceback(filtered_tb) from None\n",
      "    File \"/usr/local/lib/python3.11/site-packages/keras/src/engine/input_spec.py\", line 235, in assert_input_compatibility\n",
      "        raise ValueError(\n",
      "\n",
      "    ValueError: Exception encountered when calling layer 'model' (type Functional).\n",
      "    \n",
      "    Input 0 of layer \"time_distributed\" is incompatible with the layer: expected ndim=5, found ndim=2. Full shape received: (None, 0)\n",
      "    \n",
      "    Call arguments received by layer 'model' (type Functional):\n",
      "      • inputs=tf.Tensor(shape=(None, 0), dtype=float32)\n",
      "      • training=False\n",
      "      • mask=None\n",
      "\n",
      "127.0.0.1 - - [04/Oct/2023 16:00:08] \"GET / HTTP/1.1\" 200 -\n",
      "INFO:werkzeug:127.0.0.1 - - [04/Oct/2023 16:00:08] \"GET / HTTP/1.1\" 200 -\n",
      "127.0.0.1 - - [04/Oct/2023 16:00:12] \"\u001b[33mGET /videos/pexels-mikhail-nilov-8655759%20(1080p).mp4 HTTP/1.1\u001b[0m\" 404 -\n",
      "INFO:werkzeug:127.0.0.1 - - [04/Oct/2023 16:00:12] \"\u001b[33mGET /videos/pexels-mikhail-nilov-8655759%20(1080p).mp4 HTTP/1.1\u001b[0m\" 404 -\n",
      "127.0.0.1 - - [04/Oct/2023 16:00:15] \"GET / HTTP/1.1\" 200 -\n",
      "INFO:werkzeug:127.0.0.1 - - [04/Oct/2023 16:00:15] \"GET / HTTP/1.1\" 200 -\n",
      "127.0.0.1 - - [04/Oct/2023 16:00:22] \"\u001b[33mGET /videos/v_ArmFlapping_05.xml HTTP/1.1\u001b[0m\" 404 -\n",
      "INFO:werkzeug:127.0.0.1 - - [04/Oct/2023 16:00:22] \"\u001b[33mGET /videos/v_ArmFlapping_05.xml HTTP/1.1\u001b[0m\" 404 -\n",
      "127.0.0.1 - - [04/Oct/2023 16:00:24] \"GET / HTTP/1.1\" 200 -\n",
      "INFO:werkzeug:127.0.0.1 - - [04/Oct/2023 16:00:24] \"GET / HTTP/1.1\" 200 -\n",
      "127.0.0.1 - - [04/Oct/2023 16:03:05] \"GET / HTTP/1.1\" 200 -\n",
      "INFO:werkzeug:127.0.0.1 - - [04/Oct/2023 16:03:05] \"GET / HTTP/1.1\" 200 -\n"
     ]
    }
   ],
   "source": [
    "import tensorflow as tf\n",
    "import cv2\n",
    "import numpy as np\n",
    "import time\n",
    "import os\n",
    "from flask import Flask, render_template, request, send_from_directory\n",
    "import json\n",
    "\n",
    "app = Flask(__name__, static_url_path=\"\")\n",
    "\n",
    "IMAGE_SIZE = (224, 224, 3)\n",
    "model = None\n",
    "\n",
    "def predict_model(model, video):\n",
    "    cap = cv2.VideoCapture(video)\n",
    "\n",
    "    data_matrix = []\n",
    "\n",
    "    # read in the frames\n",
    "    while True:\n",
    "        ret, frame = cap.read()\n",
    "        if not ret:\n",
    "            break\n",
    "\n",
    "        image = cv2.resize(frame, (IMAGE_SIZE[0], IMAGE_SIZE[1])) # resize\n",
    "        data_matrix.append(image)\n",
    "\n",
    "    cur_time = time.time()\n",
    "    prediction = model.predict(np.array([data_matrix]))\n",
    "    pred_time = time.time() - cur_time\n",
    "    print(prediction)\n",
    "    text_pred = \"Hand Flapping\" if prediction >= 0.5 else \"No Hand Flapping\"\n",
    "\n",
    "    cap.release()\n",
    "    return round(pred_time, 2), (text_pred, round(max([(1 - prediction)[0][0], prediction[0][0]]), 2))\n",
    "\n",
    "@app.before_first_request\n",
    "def before_first_request():\n",
    "    global model\n",
    "    model = tf.keras.models.load_model(\"MBNet\")\n",
    "\n",
    "@app.route(\"/\")\n",
    "def main():\n",
    "    return app.send_static_file('demo.html')\n",
    "\n",
    "@app.route(\"/predict\", methods=['POST', 'GET'])\n",
    "def predict():\n",
    "    data = request.get_json()\n",
    "    file_name = data['file']\n",
    "    if not file_name.endswith(\".mov\") and not file_name.endswith(\".mp4\"):\n",
    "        return \"Invalid File!\"\n",
    "\n",
    "    pred_time, (prediction_class, confidence) = predict_model(model, f\"static/videos/{file_name}\")\n",
    "    print(pred_time, prediction_class, confidence)\n",
    "    return {\"time\": str(pred_time), \"prediction\": prediction_class, \"confidence\": str(confidence)}\n",
    "\n",
    "if __name__ == \"__main__\":\n",
    "    #app.run(debug=True, port=8000, host=\"localhost\",use_reloader=False)\n",
    "    #app.run(host='localhost',port=4455,debug=True) \n",
    "    app.run(debug=True, port=8049, use_reloader=False)\n",
    "\n",
    "    \n"
   ]
  },
  {
   "cell_type": "code",
   "execution_count": null,
   "id": "07909220-e8ec-45d6-a2c7-0684a3aea57f",
   "metadata": {},
   "outputs": [],
   "source": []
  }
 ],
 "metadata": {
  "kernelspec": {
   "display_name": "Python 3 (ipykernel)",
   "language": "python",
   "name": "python3"
  },
  "language_info": {
   "codemirror_mode": {
    "name": "ipython",
    "version": 3
   },
   "file_extension": ".py",
   "mimetype": "text/x-python",
   "name": "python",
   "nbconvert_exporter": "python",
   "pygments_lexer": "ipython3",
   "version": "3.11.4"
  }
 },
 "nbformat": 4,
 "nbformat_minor": 5
}
